Workbook

Sheet Read Me
A1: CLINICAL TRIAL DATA QUALITY & SAFETY MONITORING | B1: Description
B2: Portfolio demonstration using entirely synthetic data. No real patient data is included.
A3: Purpose | B3: Demonstrate clinical data review: rule-based validation, issue logging through a query workflow, and descriptive safety summaries.
A4: Study setting | B4: Simulated two-arm trial (Placebo vs Treatment A), 5 sites, visits at Screening, Baseline, Week 4, Week 8 and Week 12. Data as-of date is on the Check Rules sheet.
A5: Sheet guide | B5: Subjects / Visits / Adverse Events = the data (last column of each is a live formula check). Data Checks = every flagged record. Query Log = queries raised to sites, with status and days open. Check Rules = editable limits and the rule list. Dashboard = summaries and charts.
A6: How the checks work | B6: Each data row has a Row_Check formula (nested IF, COUNTIF, INDEX/MATCH) that returns OK or the first problem found. Limits (age, weight, BP) are read from Check Rules, so changing a limit updates all checks. Fix a value in the data and its flag turns to OK.
A7: Suggested workflow | B7: 1) Read Check Rules. 2) Filter Row_Check on each data sheet for anything not OK. 3) See each flag in Data Checks. 4) Read the matching query in Query Log. 5) Review the Dashboard.
A8: Data dictionary | B8: Subjects = participant-level; Visits = visit-level; Adverse Events = event-level; Treatment_Arm on Adverse Events is looked up from Subjects.
A9: Validation rules | B9: Unique subject IDs; age 18-85; weight 35-200 kg; systolic BP 70-220; diastolic BP 40-130; diastolic below systolic; visit and AE dates not before enrollment; required fields; subject linkage to the register. 15 rules in total.
A10: Planted issues | B10: Realistic errors were deliberately placed in the synthetic data (duplicate ID, out-of-range values, missing fields, unregistered subject, date errors) so the checks have something to find. 17 queries were raised; 3 are closed with the data corrected, so those flags now show OK.
A11: Clinical caution | B11: Out-of-range values are review flags, not proof of error. Confirm against source records and approved procedures.
A12: Safety caution | B12: Seriousness is not severity. This project does not assess causality, expectedness, or regulatory reportability.
A13: Important limitation | B13: Educational exercise, not a validated clinical system or substitute for protocol/SOP review.
A14: Portfolio credit | B14: Created as a learning project by Shaziya Thabassum Javid. All records are synthetic.

Sheet Dashboard
A1: CLINICAL TRIAL DATA QUALITY & SAFETY DASHBOARD
A2: Synthetic educational dataset | All findings require source verification
A3: Data as of: | B3: ='Check Rules'!B11 -> 46142
A4: Metric | B4: Value | C4: Interpretation
A5: Unique subjects | B5: =SUMPRODUCT(1/COUNTIF(Subjects!$A$2:$A$82,Subjects!$A$2:$A$82)) -> 80 | C5: Distinct participants (duplicate row not double-counted)
A6: Subject register rows | B6: =COUNTA(Subjects!$A$2:$A$82) -> 81 | C6: Includes one intentional duplicate row
A7: Visit records | B7: =COUNTA(Visits!$A$2:$A$293) -> 292 | C7: Visit-level records, including scheduled and missed
A8: Visits completed (of due) | B8: =COUNTIF(Visits!$H$2:$H$293,"Complete")/(COUNTIF(Visits!$H$2:$H$293,"Complete")+COUNTIF(Visits!$H$2:$H$293,"Missed")) -> 0.99649123 | C8: Completed visits divided by visits that were due
A9: Adverse event records | B9: =COUNTA('Adverse Events'!$A$2:$A$61) -> 60 | C9: Reported event records
A10: Serious AEs (SAEs) | B10: =COUNTIF('Adverse Events'!$F$2:$F$61,"Yes") -> 8 | C10: Seriousness criteria met; not the same as severity
A11: Open review flags (live) | B11: =COUNTIF(Subjects!$H$2:$H$82,"<>OK")+COUNTIF(Visits!$I$2:$I$293,"<>OK")+COUNTIF('Adverse Events'!$J$2:$J$61,"<>OK") -> 16 | C11: Records failing a check right now; review items, not confirmed errors
A12: Queries not yet closed | B12: =COUNTIF('Query Log'!$H$2:$H$18,"<>Closed") -> 14 | C12: Queries raised to sites without a final resolution
A13: Average days open (not closed) | B13: =AVERAGEIFS('Query Log'!$L$2:$L$18,'Query Log'!$H$2:$H$18,"<>Closed") -> 32.428571 | C13: Query aging as of the data date
A15: Adverse events by reported severity
A16: Severity | B16: Count | C16: % of AEs
A17: Mild | B17: =COUNTIF('Adverse Events'!$E$2:$E$61,A17) -> 37 | C17: =B17/$B$9 -> 0.61666667
A18: Moderate | B18: =COUNTIF('Adverse Events'!$E$2:$E$61,A18) -> 11 | C18: =B18/$B$9 -> 0.18333333
A19: Severe | B19: =COUNTIF('Adverse Events'!$E$2:$E$61,A19) -> 11 | C19: =B19/$B$9 -> 0.18333333
A20: Missing | B20: =COUNTBLANK('Adverse Events'!$E$2:$E$61) -> 1 | C20: =B20/$B$9 -> 0.016666667
A22: Treatment arm summary
A23: Arm | B23: Subjects | C23: Withdrawn | D23: Withdrawn % | E23: AE records | F23: AEs per subject | G23: Serious AEs | H23: % AEs related / possibly related
A24: Placebo | B24: =SUMPRODUCT((Subjects!$F$2:$F$82=A24)/COUNTIF(Subjects!$A$2:$A$82,Subjects!$A$2:$A$82)) -> 37 | C24: =SUMPRODUCT((Subjects!$F$2:$F$82=A24)*(Subjects!$G$2:$G$82="Withdrawn")/COUNTIF(Subjects!$A$2:$A$82,Subjects!$A$2:$A$82)) -> 16 | D24: =IFERROR(C24/B24,0) -> 0.43243243 | E24: =COUNTIF('Adverse Events'!$I$2:$I$61,A24) -> 23 | F24: =IFERROR(E24/B24,0) -> 0.62162162 | G24: =COUNTIFS('Adverse Events'!$I$2:$I$61,A24,'Adverse Events'!$F$2:$F$61,"Yes") -> 3 | H24: =IFERROR((COUNTIFS('Adverse Events'!$I$2:$I$61,A24,'Adverse Events'!$G$2:$G$61,"Related")+COUNTIFS('Adverse Events'!$I$2:$I$61,A24,'Adverse Events'!$G$2:$G$61,"Possibly related"))/E24,0) -> 0.26086957
A25: Treatment A | B25: =SUMPRODUCT((Subjects!$F$2:$F$82=A25)/COUNTIF(Subjects!$A$2:$A$82,Subjects!$A$2:$A$82)) -> 42 | C25: =SUMPRODUCT((Subjects!$F$2:$F$82=A25)*(Subjects!$G$2:$G$82="Withdrawn")/COUNTIF(Subjects!$A$2:$A$82,Subjects!$A$2:$A$82)) -> 15 | D25: =IFERROR(C25/B25,0) -> 0.35714286 | E25: =COUNTIF('Adverse Events'!$I$2:$I$61,A25) -> 35 | F25: =IFERROR(E25/B25,0) -> 0.83333333 | G25: =COUNTIFS('Adverse Events'!$I$2:$I$61,A25,'Adverse Events'!$F$2:$F$61,"Yes") -> 5 | H25: =IFERROR((COUNTIFS('Adverse Events'!$I$2:$I$61,A25,'Adverse Events'!$G$2:$G$61,"Related")+COUNTIFS('Adverse Events'!$I$2:$I$61,A25,'Adverse Events'!$G$2:$G$61,"Possibly related"))/E25,0) -> 0.6
A26: Note: one subject has no arm recorded and one AE belongs to an unregistered subject; both are flagged, so arm totals are below overall totals.
A28: Site data-quality summary
A29: Site | B29: Subjects | C29: Visit records | D29: Flagged records | E29: Flag rate
A30: SITE-001 | B30: =SUMPRODUCT((Subjects!$B$2:$B$82=A30)/COUNTIF(Subjects!$A$2:$A$82,Subjects!$A$2:$A$82)) -> 22 | C30: =COUNTIF(Visits!$B$2:$B$293,A30) -> 70 | D30: =COUNTIFS(Subjects!$B$2:$B$82,A30,Subjects!$H$2:$H$82,"<>OK")+COUNTIFS(Visits!$B$2:$B$293,A30,Visits!$I$2:$I$293,"<>OK") -> 4 | E30: =D30/(COUNTIF(Subjects!$B$2:$B$82,A30)+C30) -> 0.043010753
A31: SITE-002 | B31: =SUMPRODUCT((Subjects!$B$2:$B$82=A31)/COUNTIF(Subjects!$A$2:$A$82,Subjects!$A$2:$A$82)) -> 14 | C31: =COUNTIF(Visits!$B$2:$B$293,A31) -> 48 | D31: =COUNTIFS(Subjects!$B$2:$B$82,A31,Subjects!$H$2:$H$82,"<>OK")+COUNTIFS(Visits!$B$2:$B$293,A31,Visits!$I$2:$I$293,"<>OK") -> 2 | E31: =D31/(COUNTIF(Subjects!$B$2:$B$82,A31)+C31) -> 0.032258065
A32: SITE-003 | B32: =SUMPRODUCT((Subjects!$B$2:$B$82=A32)/COUNTIF(Subjects!$A$2:$A$82,Subjects!$A$2:$A$82)) -> 16 | C32: =COUNTIF(Visits!$B$2:$B$293,A32) -> 64 | D32: =COUNTIFS(Subjects!$B$2:$B$82,A32,Subjects!$H$2:$H$82,"<>OK")+COUNTIFS(Visits!$B$2:$B$293,A32,Visits!$I$2:$I$293,"<>OK") -> 2 | E32: =D32/(COUNTIF(Subjects!$B$2:$B$82,A32)+C32) -> 0.025
A33: SITE-004 | B33: =SUMPRODUCT((Subjects!$B$2:$B$82=A33)/COUNTIF(Subjects!$A$2:$A$82,Subjects!$A$2:$A$82)) -> 17 | C33: =COUNTIF(Visits!$B$2:$B$293,A33) -> 66 | D33: =COUNTIFS(Subjects!$B$2:$B$82,A33,Subjects!$H$2:$H$82,"<>OK")+COUNTIFS(Visits!$B$2:$B$293,A33,Visits!$I$2:$I$293,"<>OK") -> 3 | E33: =D33/(COUNTIF(Subjects!$B$2:$B$82,A33)+C33) -> 0.036144578
A34: SITE-005 | B34: =SUMPRODUCT((Subjects!$B$2:$B$82=A34)/COUNTIF(Subjects!$A$2:$A$82,Subjects!$A$2:$A$82)) -> 11 | C34: =COUNTIF(Visits!$B$2:$B$293,A34) -> 44 | D34: =COUNTIFS(Subjects!$B$2:$B$82,A34,Subjects!$H$2:$H$82,"<>OK")+COUNTIFS(Visits!$B$2:$B$293,A34,Visits!$I$2:$I$293,"<>OK") -> 1 | E34: =D34/(COUNTIF(Subjects!$B$2:$B$82,A34)+C34) -> 0.018181818
A36: Data flags by domain (live)
A37: Domain | B37: Flagged records | C37: Total records | D37: Flag rate
A38: Subjects | B38: =COUNTIF(Subjects!$H$2:$H$82,"<>OK") -> 5 | C38: =COUNTA(Subjects!$A$2:$A$82) -> 81 | D38: =B38/C38 -> 0.061728395
A39: Visits | B39: =COUNTIF(Visits!$I$2:$I$293,"<>OK") -> 7 | C39: =COUNTA(Visits!$A$2:$A$293) -> 292 | D39: =B39/C39 -> 0.023972603
A40: Adverse Events | B40: =COUNTIF('Adverse Events'!$J$2:$J$61,"<>OK") -> 4 | C40: =COUNTA('Adverse Events'!$A$2:$A$61) -> 60 | D40: =B40/C40 -> 0.066666667
A42: Query status
A43: Status | B43: Queries
A44: Open | B44: =COUNTIF('Query Log'!$H$2:$H$18,A44) -> 10
A45: Sent to site | B45: =COUNTIF('Query Log'!$H$2:$H$18,A45) -> 3
...

Sheet Subjects
A1: Subject_ID | B1: Site_ID | C1: Enrollment_Date | D1: Age | E1: Sex | F1: Treatment_Arm | G1: Study_Status | H1: Row_Check
A2: SUBJ-001 | B2: SITE-001 | C2: 46028 | D2: 65 | E2: Male | F2: Treatment A | G2: Completed | H2: =IF(COUNTBLANK(A2:G2)>0,"Missing field",IF(COUNTIF($A$2:$A$82,A2)>1,"Duplicate subject ID",IF(OR(D2<'Check Rules'!$B$3,D2>'Check Rules'!$B$4),"Age out of range","OK"))) -> OK
A3: SUBJ-002 | B3: SITE-002 | C3: 46074 | D3: 24 | E3: Female | F3: Placebo | G3: Completed | H3: =IF(COUNTBLANK(A3:G3)>0,"Missing field",IF(COUNTIF($A$2:$A$82,A3)>1,"Duplicate subject ID",IF(OR(D3<'Check Rules'!$B$3,D3>'Check Rules'!$B$4),"Age out of range","OK"))) -> OK
A4: SUBJ-003 | B4: SITE-001 | C4: 46032 | D4: 31 | E4: Female | F4: Treatment A | G4: Withdrawn | H4: =IF(COUNTBLANK(A4:G4)>0,"Missing field",IF(COUNTIF($A$2:$A$82,A4)>1,"Duplicate subject ID",IF(OR(D4<'Check Rules'!$B$3,D4>'Check Rules'!$B$4),"Age out of range","OK"))) -> OK
A5: SUBJ-004 | B5: SITE-002 | C5: 46072 | D5: 59 | E5: Male | F5: Treatment A | G5: Ongoing | H5: =IF(COUNTBLANK(A5:G5)>0,"Missing field",IF(COUNTIF($A$2:$A$82,A5)>1,"Duplicate subject ID",IF(OR(D5<'Check Rules'!$B$3,D5>'Check Rules'!$B$4),"Age out of range","OK"))) -> OK
A6: SUBJ-005 | B6: SITE-005 | C6: 46044 | D6: 69 | E6: Female | F6: Treatment A | G6: Withdrawn | H6: =IF(COUNTBLANK(A6:G6)>0,"Missing field",IF(COUNTIF($A$2:$A$82,A6)>1,"Duplicate subject ID",IF(OR(D6<'Check Rules'!$B$3,D6>'Check Rules'!$B$4),"Age out of range","OK"))) -> OK
A7: SUBJ-006 | B7: SITE-004 | C7: 46048 | D7: 35 | E7: Female | F7: Treatment A | G7: Ongoing | H7: =IF(COUNTBLANK(A7:G7)>0,"Missing field",IF(COUNTIF($A$2:$A$82,A7)>1,"Duplicate subject ID",IF(OR(D7<'Check Rules'!$B$3,D7>'Check Rules'!$B$4),"Age out of range","OK"))) -> OK
A8: SUBJ-007 | B8: SITE-001 | C8: 46032 | D8: 42 | E8: Female | F8: Placebo | G8: Ongoing | H8: =IF(COUNTBLANK(A8:G8)>0,"Missing field",IF(COUNTIF($A$2:$A$82,A8)>1,"Duplicate subject ID",IF(OR(D8<'Check Rules'!$B$3,D8>'Check Rules'!$B$4),"Age out of range","OK"))) -> OK
A9: SUBJ-008 | B9: SITE-005 | C9: 46043 | D9: 69 | E9: Female | F9: Placebo | G9: Withdrawn | H9: =IF(COUNTBLANK(A9:G9)>0,"Missing field",IF(COUNTIF($A$2:$A$82,A9)>1,"Duplicate subject ID",IF(OR(D9<'Check Rules'!$B$3,D9>'Check Rules'!$B$4),"Age out of range","OK"))) -> OK
A10: SUBJ-009 | B10: SITE-001 | C10: 46051 | D10: 23 | E10: Male | F10: Placebo | G10: Withdrawn | H10: =IF(COUNTBLANK(A10:G10)>0,"Missing field",IF(COUNTIF($A$2:$A$82,A10)>1,"Duplicate subject ID",IF(OR(D10<'Check Rules'!$B$3,D10>'Check Rules'!$B$4),"Age out of range","OK"))) -> OK
A11: SUBJ-010 | B11: SITE-002 | C11: 46072 | D11: 22 | E11: Female | F11: Treatment A | G11: Ongoing | H11: =IF(COUNTBLANK(A11:G11)>0,"Missing field",IF(COUNTIF($A$2:$A$82,A11)>1,"Duplicate subject ID",IF(OR(D11<'Check Rules'!$B$3,D11>'Check Rules'!$B$4),"Age out of range","OK"))) -> OK
A12: SUBJ-011 | B12: SITE-001 | C12: 46041 | D12: 73 | E12: Female | F12: Placebo | G12: Ongoing | H12: =IF(COUNTBLANK(A12:G12)>0,"Missing field",IF(COUNTIF($A$2:$A$82,A12)>1,"Duplicate subject ID",IF(OR(D12<'Check Rules'!$B$3,D12>'Check Rules'!$B$4),"Age out of range","OK"))) -> Duplicate subject ID
A13: SUBJ-012 | B13: SITE-004 | C13: 46067 | D13: 71 | E13: Male | F13: Treatment A | G13: Ongoing | H13: =IF(COUNTBLANK(A13:G13)>0,"Missing field",IF(COUNTIF($A$2:$A$82,A13)>1,"Duplicate subject ID",IF(OR(D13<'Check Rules'!$B$3,D13>'Check Rules'!$B$4),"Age out of range","OK"))) -> OK
... A52: SUBJ-051 | B52: SITE-001 | C52: 46063 | D52: 33 | E52: Female | F52: Treatment A | G52: Ongoing | H52: =IF(COUNTBLANK(A52:G52)>0,"Missing field",IF(COUNTIF($A$2:$A$82,A52)>1,"Duplicate subject ID",IF(OR(D52<'Check Rules'!$B$3,D52>'Check Rules'!$B$4),"Age out of range","OK"))) -> OK
A53: SUBJ-052 | B53: SITE-005 | C53: 46063 | D53: 51 | F53: Placebo | G53: Completed | H53: =IF(COUNTBLANK(A53:G53)>0,"Missing field",IF(COUNTIF($A$2:$A$82,A53)>1,"Duplicate subject ID",IF(OR(D53<'Check Rules'!$B$3,D53>'Check Rules'!$B$4),"Age out of range","OK"))) -> Missing field
A54: SUBJ-053 | B54: SITE-003 | C54: 46042 | D54: 34 | E54: Male | F54: Treatment A | G54: Withdrawn | H54: =IF(COUNTBLANK(A54:G54)>0,"Missing field",IF(COUNTIF($A$2:$A$82,A54)>1,"Duplicate subject ID",IF(OR(D54<'Check Rules'!$B$3,D54>'Check Rules'!$B$4),"Age out of range","OK"))) -> OK
A55: SUBJ-054 | B55: SITE-003 | C55: 46056 | D55: 38 | E55: Female | F55: Treatment A | G55: Ongoing | H55: =IF(COUNTBLANK(A55:G55)>0,"Missing field",IF(COUNTIF($A$2:$A$82,A55)>1,"Duplicate subject ID",IF(OR(D55<'Check Rules'!$B$3,D55>'Check Rules'!$B$4),"Age out of range","OK"))) -> OK
A56: SUBJ-055 | B56: SITE-005 | C56: 46063 | D56: 24 | E56: Female | F56: Treatment A | G56: Withdrawn | H56: =IF(COUNTBLANK(A56:G56)>0,"Missing field",IF(COUNTIF($A$2:$A$82,A56)>1,"Duplicate subject ID",IF(OR(D56<'Check Rules'!$B$3,D56>'Check Rules'!$B$4),"Age out of range","OK"))) -> OK
A57: SUBJ-056 | B57: SITE-003 | C57: 46035 | D57: 77 | E57: Male | F57: Treatment A | G57: Completed | H57: =IF(COUNTBLANK(A57:G57)>0,"Missing field",IF(COUNTIF($A$2:$A$82,A57)>1,"Duplicate subject ID",IF(OR(D57<'Check Rules'!$B$3,D57>'Check Rules'!$B$4),"Age out of range","OK"))) -> OK
A58: SUBJ-057 | B58: SITE-003 | C58: 46045 | D58: 28 | E58: Male | F58: Placebo | G58: Withdrawn | H58: =IF(COUNTBLANK(A58:G58)>0,"Missing field",IF(COUNTIF($A$2:$A$82,A58)>1,"Duplicate subject ID",IF(OR(D58<'Check Rules'!$B$3,D58>'Check Rules'!$B$4),"Age out of range","OK"))) -> OK
A59: SUBJ-058 | B59: SITE-005 | C59: 46027 | D59: 60 | E59: Male | F59: Treatment A | G59: Completed | H59: =IF(COUNTBLANK(A59:G59)>0,"Missing field",IF(COUNTIF($A$2:$A$82,A59)>1,"Duplicate subject ID",IF(OR(D59<'Check Rules'!$B$3,D59>'Check Rules'!$B$4),"Age out of range","OK"))) -> OK
A60: SUBJ-059 | B60: SITE-003 | C60: 46034 | D60: 74 | E60: Female | F60: Treatment A | G60: Ongoing | H60: =IF(COUNTBLANK(A60:G60)>0,"Missing field",IF(COUNTIF($A$2:$A$82,A60)>1,"Duplicate subject ID",IF(OR(D60<'Check Rules'!$B$3,D60>'Check Rules'!$B$4),"Age out of range","OK"))) -> OK
A61: SUBJ-060 | B61: SITE-003 | C61: 46065 | D61: 31 | E61: Male | F61: Treatment A | G61: Withdrawn | H61: =IF(COUNTBLANK(A61:G61)>0,"Missing field",IF(COUNTIF($A$2:$A$82,A61)>1,"Duplicate subject ID",IF(OR(D61<'Check Rules'!$B$3,D61>'Check Rules'!$B$4),"Age out of range","OK"))) -> OK
A62: SUBJ-061 | B62: SITE-003 | C62: 46059 | D62: 49 | E62: Male | F62: Treatment A | G62: Completed | H62: =IF(COUNTBLANK(A62:G62)>0,"Missing field",IF(COUNTIF($A$2:$A$82,A62)>1,"Duplicate subject ID",IF(OR(D62<'Check Rules'!$B$3,D62>'Check Rules'!$B$4),"Age out of range","OK"))) -> OK
A63: SUBJ-062 | B63: SITE-004 | C63: 46044 | D63: 20 | E63: Female | F63: Placebo | G63: Completed | H63: =IF(COUNTBLANK(A63:G63)>0,"Missing field",IF(COUNTIF($A$2:$A$82,A63)>1,"Duplicate subject ID",IF(OR(D63<'Check Rules'!$B$3,D63>'Check Rules'!$B$4),"Age out of range","OK"))) -> OK
A64: SUBJ-063 | B64: SITE-003 | C64: 46037 | D64: 65 | E64: Male | F64: Placebo | G64: Withdrawn | H64: =IF(COUNTBLANK(A64:G64)>0,"Missing field",IF(COUNTIF($A$2:$A$82,A64)>1,"Duplicate subject ID",IF(OR(D64<'Check Rules'!$B$3,D64>'Check Rules'!$B$4),"Age out of range","OK"))) -> OK
A65: SUBJ-064 | B65: SITE-001 | C65: 46034 | D65: 22 | E65: Female | F65: Treatment A | G65: Ongoing | H65: =IF(COUNTBLANK(A65:G65)>0,"Missing field",IF(COUNTIF($A$2:$A$82,A65)>1,"Duplicate subject ID",IF(OR(D65<'Check Rules'!$B$3,D65>'Check Rules'!$B$4),"Age out of range","OK"))) -> OK
A66: SUBJ-065 | B66: SITE-005 | C66: 46062 | D66: 27 | E66: Male | F66: Treatment A | G66: Completed | H66: =IF(COUNTBLANK(A66:G66)>0,"Missing field",IF(COUNTIF($A$2:$A$82,A66)>1,"Duplicate subject ID",IF(OR(D66<'Check Rules'!$B$3,D66>'Check Rules'!$B$4),"Age out of range","OK"))) -> OK
A67: SUBJ-066 | B67: SITE-003 | C67: 46050 | D67: 75 | E67: Female | G67: Completed | H67: =IF(COUNTBLANK(A67:G67)>0,"Missing field",IF(COUNTIF($A$2:$A$82,A67)>1,"Duplicate subject ID",IF(OR(D67<'Check Rules'!$B$3,D67>'Check Rules'!$B$4),"Age out of range","OK"))) -> Missing field
A68: SUBJ-067 | B68: SITE-002 | C68: 46069 | D68: 24 | E68: Male | F68: Placebo | G68: Withdrawn | H68: =IF(COUNTBLANK(A68:G68)>0,"Missing field",IF(COUNTIF($A$2:$A$82,A68)>1,"Duplicate subject ID",IF(OR(D68<'Check Rules'!$B$3,D68>'Check Rules'!$B$4),"Age out of range","OK"))) -> OK
A69: SUBJ-068 | B69: SITE-002 | C69: 46042 | D69: 73 | E69: Female | F69: Treatment A | G69: Ongoing | H69: =IF(COUNTBLANK(A69:G69)>0,"Missing field",IF(COUNTIF($A$2:$A$82,A69)>1,"Duplicate subject ID",IF(OR(D69<'Check Rules'!$B$3,D69>'Check Rules'!$B$4),"Age out of range","OK"))) -> OK
A70: SUBJ-069 | B70: SITE-001 | C70: 46038 | D70: 65 | E70: Male | F70: Placebo | G70: Withdrawn | H70: =IF(COUNTBLANK(A70:G70)>0,"Missing field",IF(COUNTIF($A$2:$A$82,A70)>1,"Duplicate subject ID",IF(OR(D70<'Check Rules'!$B$3,D70>'Check Rules'!$B$4),"Age out of range","OK"))) -> OK
A71: SUBJ-070 | B71: SITE-002 | C71: 46044 | D71: 28 | E71: Female | F71: Placebo | G71: Completed | H71: =IF(COUNTBLANK(A71:G71)>0,"Missing field",IF(COUNTIF($A$2:$A$82,A71)>1,"Duplicate subject ID",IF(OR(D71<'Check Rules'!$B$3,D71>'Check Rules'!$B$4),"Age out of range","OK"))) -> OK
A72: SUBJ-071 | B72: SITE-004 | C72: 46041 | D72: 30 | E72: Male | F72: Placebo | G72: Ongoing | H72: =IF(COUNTBLANK(A72:G72)>0,"Missing field",IF(COUNTIF($A$2:$A$82,A72)>1,"Duplicate subject ID",IF(OR(D72<'Check Rules'!$B$3,D72>'Check Rules'!$B$4),"Age out of range","OK"))) -> OK
A73: SUBJ-072 | B73: SITE-002 | C73: 46041 | D73: 19 | E73: Female | F73: Placebo | G73: Ongoing | H73: =IF(COUNTBLANK(A73:G73)>0,"Missing field",IF(COUNTIF($A$2:$A$82,A73)>1,"Duplicate subject ID",IF(OR(D73<'Check Rules'!$B$3,D73>'Check Rules'!$B$4),"Age out of range","OK"))) -> OK
A74: SUBJ-073 | B74: SITE-003 | C74: 46031 | D74: 91 | E74: Male | F74: Placebo | G74: Withdrawn | H74: =IF(COUNTBLANK(A74:G74)>0,"Missing field",IF(COUNTIF($A$2:$A$82,A74)>1,"Duplicate subject ID",IF(OR(D74<'Check Rules'!$B$3,D74>'Check Rules'!$B$4),"Age out of range","OK"))) -> Age out of range
A75: SUBJ-074 | B75: SITE-005 | C75: 46052 | D75: 61 | E75: Male | F75: Treatment A | G75: Completed | H75: =IF(COUNTBLANK(A75:G75)>0,"Missing field",IF(COUNTIF($A$2:$A$82,A75)>1,"Duplicate subject ID",IF(OR(D75<'Check Rules'!$B$3,D75>'Check Rules'!$B$4),"Age out of range","OK"))) -> OK
A76: SUBJ-075 | B76: SITE-003 | C76: 46038 | D76: 55 | E76: Male | F76: Treatment A | G76: Completed | H76: =IF(COUNTBLANK(A76:G76)>0,"Missing field",IF(COUNTIF($A$2:$A$82,A76)>1,"Duplicate subject ID",IF(OR(D76<'Check Rules'!$B$3,D76>'Check Rules'!$B$4),"Age out of range","OK"))) -> OK
A77: SUBJ-076 | B77: SITE-005 | C77: 46054 | D77: 40 | E77: Male | F77: Placebo | G77: Withdrawn | H77: =IF(COUNTBLANK(A77:G77)>0,"Missing field",IF(COUNTIF($A$2:$A$82,A77)>1,"Duplicate subject ID",IF(OR(D77<'Check Rules'!$B$3,D77>'Check Rules'!$B$4),"Age out of range","OK"))) -> OK
A78: SUBJ-077 | B78: SITE-005 | C78: 46034 | D78: 42 | E78: Female | F78: Placebo | G78: Completed | H78: =IF(COUNTBLANK(A78:G78)>0,"Missing field",IF(COUNTIF($A$2:$A$82,A78)>1,"Duplicate subject ID",IF(OR(D78<'Check Rules'!$B$3,D78>'Check Rules'!$B$4),"Age out of range","OK"))) -> OK
...

Sheet Visits
A1: Subject_ID | B1: Site_ID | C1: Visit_Name | D1: Visit_Date | E1: Weight_kg | F1: Systolic_BP | G1: Diastolic_BP | H1: Visit_Status | I1: Row_Check
A2: SUBJ-001 | B2: SITE-001 | C2: Screening | D2: 46028 | E2: 71.9 | F2: 127 | G2: 81 | H2: Complete | I2: =IF(COUNTIF(Subjects!$A$2:$A$82,A2)=0,"Subject not in register",IF(D2<INDEX(Subjects!$C$2:$C$82,MATCH(A2,Subjects!$A$2:$A$82,0)),"Visit before enrollment",IF(H2="Missed","Missed visit",IF(H2="Scheduled","OK",IF(E2="","Missing weight",IF(OR(E2<'Check Rules'!$B$5,E2>'Check Rules'!$B$6),"Weight out of range",IF(OR(F2<'Check Rules'!$B$7,F2>'Check Rules'!$B$8),"Systolic BP out of range",IF(OR(G2<'Check Rules'!$B$9,G2>'Check Rules'!$B$10),"Diastolic BP out of range",IF(G2>=F2,"Diastolic >= systolic","OK"))))))))) -> OK
A3: SUBJ-001 | B3: SITE-001 | C3: Baseline | D3: 46030 | E3: 72.9 | F3: 130 | G3: 77 | H3: Complete | I3: =IF(COUNTIF(Subjects!$A$2:$A$82,A3)=0,"Subject not in register",IF(D3<INDEX(Subjects!$C$2:$C$82,MATCH(A3,Subjects!$A$2:$A$82,0)),"Visit before enrollment",IF(H3="Missed","Missed visit",IF(H3="Scheduled","OK",IF(E3="","Missing weight",IF(OR(E3<'Check Rules'!$B$5,E3>'Check Rules'!$B$6),"Weight out of range",IF(OR(F3<'Check Rules'!$B$7,F3>'Check Rules'!$B$8),"Systolic BP out of range",IF(OR(G3<'Check Rules'!$B$9,G3>'Check Rules'!$B$10),"Diastolic BP out of range",IF(G3>=F3,"Diastolic >= systolic","OK"))))))))) -> OK
A4: SUBJ-001 | B4: SITE-001 | C4: Week 4 | D4: 46058 | E4: 71.5 | F4: 129 | G4: 69 | H4: Complete | I4: =IF(COUNTIF(Subjects!$A$2:$A$82,A4)=0,"Subject not in register",IF(D4<INDEX(Subjects!$C$2:$C$82,MATCH(A4,Subjects!$A$2:$A$82,0)),"Visit before enrollment",IF(H4="Missed","Missed visit",IF(H4="Scheduled","OK",IF(E4="","Missing weight",IF(OR(E4<'Check Rules'!$B$5,E4>'Check Rules'!$B$6),"Weight out of range",IF(OR(F4<'Check Rules'!$B$7,F4>'Check Rules'!$B$8),"Systolic BP out of range",IF(OR(G4<'Check Rules'!$B$9,G4>'Check Rules'!$B$10),"Diastolic BP out of range",IF(G4>=F4,"Diastolic >= systolic","OK"))))))))) -> OK
A5: SUBJ-001 | B5: SITE-001 | C5: Week 8 | D5: 46086 | E5: 71.6 | F5: 117 | G5: 65 | H5: Complete | I5: =IF(COUNTIF(Subjects!$A$2:$A$82,A5)=0,"Subject not in register",IF(D5<INDEX(Subjects!$C$2:$C$82,MATCH(A5,Subjects!$A$2:$A$82,0)),"Visit before enrollment",IF(H5="Missed","Missed visit",IF(H5="Scheduled","OK",IF(E5="","Missing weight",IF(OR(E5<'Check Rules'!$B$5,E5>'Check Rules'!$B$6),"Weight out of range",IF(OR(F5<'Check Rules'!$B$7,F5>'Check Rules'!$B$8),"Systolic BP out of range",IF(OR(G5<'Check Rules'!$B$9,G5>'Check Rules'!$B$10),"Diastolic BP out of range",IF(G5>=F5,"Diastolic >= systolic","OK"))))))))) -> OK
A6: SUBJ-001 | B6: SITE-001 | C6: Week 12 | D6: 46114 | E6: 71.1 | F6: 137 | G6: 78 | H6: Complete | I6: =IF(COUNTIF(Subjects!$A$2:$A$82,A6)=0,"Subject not in register",IF(D6<INDEX(Subjects!$C$2:$C$82,MATCH(A6,Subjects!$A$2:$A$82,0)),"Visit before enrollment",IF(H6="Missed","Missed visit",IF(H6="Scheduled","OK",IF(E6="","Missing weight",IF(OR(E6<'Check Rules'!$B$5,E6>'Check Rules'!$B$6),"Weight out of range",IF(OR(F6<'Check Rules'!$B$7,F6>'Check Rules'!$B$8),"Systolic BP out of range",IF(OR(G6<'Check Rules'!$B$9,G6>'Check Rules'!$B$10),"Diastolic BP out of range",IF(G6>=F6,"Diastolic >= systolic","OK"))))))))) -> OK
A7: SUBJ-002 | B7: SITE-002 | C7: Screening | D7: 46074 | E7: 61.4 | F7: 115 | G7: 78 | H7: Complete | I7: =IF(COUNTIF(Subjects!$A$2:$A$82,A7)=0,"Subject not in register",IF(D7<INDEX(Subjects!$C$2:$C$82,MATCH(A7,Subjects!$A$2:$A$82,0)),"Visit before enrollment",IF(H7="Missed","Missed visit",IF(H7="Scheduled","OK",IF(E7="","Missing weight",IF(OR(E7<'Check Rules'!$B$5,E7>'Check Rules'!$B$6),"Weight out of range",IF(OR(F7<'Check Rules'!$B$7,F7>'Check Rules'!$B$8),"Systolic BP out of range",IF(OR(G7<'Check Rules'!$B$9,G7>'Check Rules'!$B$10),"Diastolic BP out of range",IF(G7>=F7,"Diastolic >= systolic","OK"))))))))) -> OK
A8: SUBJ-002 | B8: SITE-002 | C8: Baseline | D8: 46076 | E8: 61.3 | F8: 121 | G8: 73 | H8: Complete | I8: =IF(COUNTIF(Subjects!$A$2:$A$82,A8)=0,"Subject not in register",IF(D8<INDEX(Subjects!$C$2:$C$82,MATCH(A8,Subjects!$A$2:$A$82,0)),"Visit before enrollment",IF(H8="Missed","Missed visit",IF(H8="Scheduled","OK",IF(E8="","Missing weight",IF(OR(E8<'Check Rules'!$B$5,E8>'Check Rules'!$B$6),"Weight out of range",IF(OR(F8<'Check Rules'!$B$7,F8>'Check Rules'!$B$8),"Systolic BP out of range",IF(OR(G8<'Check Rules'!$B$9,G8>'Check Rules'!$B$10),"Diastolic BP out of range",IF(G8>=F8,"Diastolic >= systolic","OK"))))))))) -> OK
A9: SUBJ-002 | B9: SITE-002 | C9: Week 4 | D9: 46104 | E9: 61.5 | F9: 126 | G9: 75 | H9: Complete | I9: =IF(COUNTIF(Subjects!$A$2:$A$82,A9)=0,"Subject not in register",IF(D9<INDEX(Subjects!$C$2:$C$82,MATCH(A9,Subjects!$A$2:$A$82,0)),"Visit before enrollment",IF(H9="Missed","Missed visit",IF(H9="Scheduled","OK",IF(E9="","Missing weight",IF(OR(E9<'Check Rules'!$B$5,E9>'Check Rules'!$B$6),"Weight out of range",IF(OR(F9<'Check Rules'!$B$7,F9>'Check Rules'!$B$8),"Systolic BP out of range",IF(OR(G9<'Check Rules'!$B$9,G9>'Check Rules'!$B$10),"Diastolic BP out of range",IF(G9>=F9,"Diastolic >= systolic","OK"))))))))) -> OK
A10: SUBJ-002 | B10: SITE-002 | C10: Week 8 | D10: 46132 | E10: 60.8 | F10: 115 | G10: 75 | H10: Complete | I10: =IF(COUNTIF(Subjects!$A$2:$A$82,A10)=0,"Subject not in register",IF(D10<INDEX(Subjects!$C$2:$C$82,MATCH(A10,Subjects!$A$2:$A$82,0)),"Visit before enrollment",IF(H10="Missed","Missed visit",IF(H10="Scheduled","OK",IF(E10="","Missing weight",IF(OR(E10<'Check Rules'!$B$5,E10>'Check Rules'!$B$6),"Weight out of range",IF(OR(F10<'Check Rules'!$B$7,F10>'Check Rules'!$B$8),"Systolic BP out of range",IF(OR(G10<'Check Rules'!$B$9,G10>'Check Rules'!$B$10),"Diastolic BP out of range",IF(G10>=F10,"Diastolic >= systolic","OK"))))))))) -> OK
A11: SUBJ-002 | B11: SITE-002 | C11: Week 12 | D11: 46160 | H11: Scheduled | I11: =IF(COUNTIF(Subjects!$A$2:$A$82,A11)=0,"Subject not in register",IF(D11<INDEX(Subjects!$C$2:$C$82,MATCH(A11,Subjects!$A$2:$A$82,0)),"Visit before enrollment",IF(H11="Missed","Missed visit",IF(H11="Scheduled","OK",IF(E11="","Missing weight",IF(OR(E11<'Check Rules'!$B$5,E11>'Check Rules'!$B$6),"Weight out of range",IF(OR(F11<'Check Rules'!$B$7,F11>'Check Rules'!$B$8),"Systolic BP out of range",IF(OR(G11<'Check Rules'!$B$9,G11>'Check Rules'!$B$10),"Diastolic BP out of range",IF(G11>=F11,"Diastolic >= systolic","OK"))))))))) -> OK
A12: SUBJ-003 | B12: SITE-001 | C12: Screening | D12: 46032 | E12: 72.6 | F12: 147 | G12: 71 | H12: Complete | I12: =IF(COUNTIF(Subjects!$A$2:$A$82,A12)=0,"Subject not in register",IF(D12<INDEX(Subjects!$C$2:$C$82,MATCH(A12,Subjects!$A$2:$A$82,0)),"Visit before enrollment",IF(H12="Missed","Missed visit",IF(H12="Scheduled","OK",IF(E12="","Missing weight",IF(OR(E12<'Check Rules'!$B$5,E12>'Check Rules'!$B$6),"Weight out of range",IF(OR(F12<'Check Rules'!$B$7,F12>'Check Rules'!$B$8),"Systolic BP out of range",IF(OR(G12<'Check Rules'!$B$9,G12>'Check Rules'!$B$10),"Diastolic BP out of range",IF(G12>=F12,"Diastolic >= systolic","OK"))))))))) -> OK
A13: SUBJ-003 | B13: SITE-001 | C13: Baseline | D13: 46034 | E13: 74.1 | F13: 141 | G13: 71 | H13: Complete | I13: =IF(COUNTIF(Subjects!$A$2:$A$82,A13)=0,"Subject not in register",IF(D13<INDEX(Subjects!$C$2:$C$82,MATCH(A13,Subjects!$A$2:$A$82,0)),"Visit before enrollment",IF(H13="Missed","Missed visit",IF(H13="Scheduled","OK",IF(E13="","Missing weight",IF(OR(E13<'Check Rules'!$B$5,E13>'Check Rules'!$B$6),"Weight out of range",IF(OR(F13<'Check Rules'!$B$7,F13>'Check Rules'!$B$8),"Systolic BP out of range",IF(OR(G13<'Check Rules'!$B$9,G13>'Check Rules'!$B$10),"Diastolic BP out of range",IF(G13>=F13,"Diastolic >= systolic","OK"))))))))) -> OK
A14: SUBJ-003 | B14: SITE-001 | C14: Week 4 | D14: 46062 | E14: 73.3 | F14: 150 | G14: 75 | H14: Complete | I14: =IF(COUNTIF(Subjects!$A$2:$A$82,A14)=0,"Subject not in register",IF(D14<INDEX(Subjects!$C$2:$C$82,MATCH(A14,Subjects!$A$2:$A$82,0)),"Visit before enrollment",IF(H14="Missed","Missed visit",IF(H14="Scheduled","OK",IF(E14="","Missing weight",IF(OR(E14<'Check Rules'!$B$5,E14>'Check Rules'!$B$6),"Weight out of range",IF(OR(F14<'Check Rules'!$B$7,F14>'Check Rules'!$B$8),"Systolic BP out of range",IF(OR(G14<'Check Rules'!$B$9,G14>'Check Rules'!$B$10),"Diastolic BP out of range",IF(G14>=F14,"Diastolic >= systolic","OK"))))))))) -> OK
A15: SUBJ-004 | B15: SITE-002 | C15: Screening | D15: 46072 | E15: 64.8 | F15: 134 | G15: 72 | H15: Complete | I15: =IF(COUNTIF(Subjects!$A$2:$A$82,A15)=0,"Subject not in register",IF(D15<INDEX(Subjects!$C$2:$C$82,MATCH(A15,Subjects!$A$2:$A$82,0)),"Visit before enrollment",IF(H15="Missed","Missed visit",IF(H15="Scheduled","OK",IF(E15="","Missing weight",IF(OR(E15<'Check Rules'!$B$5,E15>'Check Rules'!$B$6),"Weight out of range",IF(OR(F15<'Check Rules'!$B$7,F15>'Check Rules'!$B$8),"Systolic BP out of range",IF(OR(G15<'Check Rules'!$B$9,G15>'Check Rules'!$B$10),"Diastolic BP out of range",IF(G15>=F15,"Diastolic >= systolic","OK"))))))))) -> OK
A16: SUBJ-004 | B16: SITE-002 | C16: Baseline | D16: 46074 | E16: 63.7 | F16: 131 | G16: 83 | H16: Complete | I16: =IF(COUNTIF(Subjects!$A$2:$A$82,A16)=0,"Subject not in register",IF(D16<INDEX(Subjects!$C$2:$C$82,MATCH(A16,Subjects!$A$2:$A$82,0)),"Visit before enrollment",IF(H16="Missed","Missed visit",IF(H16="Scheduled","OK",IF(E16="","Missing weight",IF(OR(E16<'Check Rules'!$B$5,E16>'Check Rules'!$B$6),"Weight out of range",IF(OR(F16<'Check Rules'!$B$7,F16>'Check Rules'!$B$8),"Systolic BP out of range",IF(OR(G16<'Check Rules'!$B$9,G16>'Check Rules'!$B$10),"Diastolic BP out of range",IF(G16>=F16,"Diastolic >= systolic","OK"))))))))) -> OK
A17: SUBJ-005 | B17: SITE-005 | C17: Screening | D17: 46044 | E17: 74.2 | F17: 114 | G17: 79 | H17: Complete | I17: =IF(COUNTIF(Subjects!$A$2:$A$82,A17)=0,"Subject not in register",IF(D17<INDEX(Subjects!$C$2:$C$82,MATCH(A17,Subjects!$A$2:$A$82,0)),"Visit before enrollment",IF(H17="Missed","Missed visit",IF(H17="Scheduled","OK",IF(E17="","Missing weight",IF(OR(E17<'Check Rules'!$B$5,E17>'Check Rules'!$B$6),"Weight out of range",IF(OR(F17<'Check Rules'!$B$7,F17>'Check Rules'!$B$8),"Systolic BP out of range",IF(OR(G17<'Check Rules'!$B$9,G17>'Check Rules'!$B$10),"Diastolic BP out of range",IF(G17>=F17,"Diastolic >= systolic","OK"))))))))) -> OK
A18: SUBJ-005 | B18: SITE-005 | C18: Baseline | D18: 46046 | E18: 74.5 | F18: 118 | G18: 80 | H18: Complete | I18: =IF(COUNTIF(Subjects!$A$2:$A$82,A18)=0,"Subject not in register",IF(D18<INDEX(Subjects!$C$2:$C$82,MATCH(A18,Subjects!$A$2:$A$82,0)),"Visit before enrollment",IF(H18="Missed","Missed visit",IF(H18="Scheduled","OK",IF(E18="","Missing weight",IF(OR(E18<'Check Rules'!$B$5,E18>'Check Rules'!$B$6),"Weight out of range",IF(OR(F18<'Check Rules'!$B$7,F18>'Check Rules'!$B$8),"Systolic BP out of range",IF(OR(G18<'Check Rules'!$B$9,G18>'Check Rules'!$B$10),"Diastolic BP out of range",IF(G18>=F18,"Diastolic >= systolic","OK"))))))))) -> OK
A19: SUBJ-005 | B19: SITE-005 | C19: Week 4 | D19: 46074 | E19: 71.8 | F19: 112 | G19: 78 | H19: Complete | I19: =IF(COUNTIF(Subjects!$A$2:$A$82,A19)=0,"Subject not in register",IF(D19<INDEX(Subjects!$C$2:$C$82,MATCH(A19,Subjects!$A$2:$A$82,0)),"Visit before enrollment",IF(H19="Missed","Missed visit",IF(H19="Scheduled","OK",IF(E19="","Missing weight",IF(OR(E19<'Check Rules'!$B$5,E19>'Check Rules'!$B$6),"Weight out of range",IF(OR(F19<'Check Rules'!$B$7,F19>'Check Rules'!$B$8),"Systolic BP out of range",IF(OR(G19<'Check Rules'!$B$9,G19>'Check Rules'!$B$10),"Diastolic BP out of range",IF(G19>=F19,"Diastolic >= systolic","OK"))))))))) -> OK
A20: SUBJ-006 | B20: SITE-004 | C20: Screening | D20: 46048 | E20: 81.1 | F20: 121 | G20: 81 | H20: Complete | I20: =IF(COUNTIF(Subjects!$A$2:$A$82,A20)=0,"Subject not in register",IF(D20<INDEX(Subjects!$C$2:$C$82,MATCH(A20,Subjects!$A$2:$A$82,0)),"Visit before enrollment",IF(H20="Missed","Missed visit",IF(H20="Scheduled","OK",IF(E20="","Missing weight",IF(OR(E20<'Check Rules'!$B$5,E20>'Check Rules'!$B$6),"Weight out of range",IF(OR(F20<'Check Rules'!$B$7,F20>'Check Rules'!$B$8),"Systolic BP out of range",IF(OR(G20<'Check Rules'!$B$9,G20>'Check Rules'!$B$10),"Diastolic BP out of range",IF(G20>=F20,"Diastolic >= systolic","OK"))))))))) -> OK
A21: SUBJ-006 | B21: SITE-004 | C21: Baseline | D21: 46050 | E21: 80.5 | F21: 115 | G21: 77 | H21: Complete | I21: =IF(COUNTIF(Subjects!$A$2:$A$82,A21)=0,"Subject not in register",IF(D21<INDEX(Subjects!$C$2:$C$82,MATCH(A21,Subjects!$A$2:$A$82,0)),"Visit before enrollment",IF(H21="Missed","Missed visit",IF(H21="Scheduled","OK",IF(E21="","Missing weight",IF(OR(E21<'Check Rules'!$B$5,E21>'Check Rules'!$B$6),"Weight out of range",IF(OR(F21<'Check Rules'!$B$7,F21>'Check Rules'!$B$8),"Systolic BP out of range",IF(OR(G21<'Check Rules'!$B$9,G21>'Check Rules'!$B$10),"Diastolic BP out of range",IF(G21>=F21,"Diastolic >= systolic","OK"))))))))) -> OK
A22: SUBJ-007 | B22: SITE-001 | C22: Screening | D22: 46032 | E22: 49.2 | F22: 110 | G22: 66 | H22: Complete | I22: =IF(COUNTIF(Subjects!$A$2:$A$82,A22)=0,"Subject not in register",IF(D22<INDEX(Subjects!$C$2:$C$82,MATCH(A22,Subjects!$A$2:$A$82,0)),"Visit before enrollment",IF(H22="Missed","Missed visit",IF(H22="Scheduled","OK",IF(E22="","Missing weight",IF(OR(E22<'Check Rules'!$B$5,E22>'Check Rules'!$B$6),"Weight out of range",IF(OR(F22<'Check Rules'!$B$7,F22>'Check Rules'!$B$8),"Systolic BP out of range",IF(OR(G22<'Check Rules'!$B$9,G22>'Check Rules'!$B$10),"Diastolic BP out of range",IF(G22>=F22,"Diastolic >= systolic","OK"))))))))) -> OK
A23: SUBJ-007 | B23: SITE-001 | C23: Baseline | D23: 46011 | E23: 49.1 | F23: 121 | G23: 69 | H23: Complete | I23: =IF(COUNTIF(Subjects!$A$2:$A$82,A23)=0,"Subject not in register",IF(D23<INDEX(Subjects!$C$2:$C$82,MATCH(A23,Subjects!$A$2:$A$82,0)),"Visit before enrollment",IF(H23="Missed","Missed visit",IF(H23="Scheduled","OK",IF(E23="","Missing weight",IF(OR(E23<'Check Rules'!$B$5,E23>'Check Rules'!$B$6),"Weight out of range",IF(OR(F23<'Check Rules'!$B$7,F23>'Check Rules'!$B$8),"Systolic BP out of range",IF(OR(G23<'Check Rules'!$B$9,G23>'Check Rules'!$B$10),"Diastolic BP out of range",IF(G23>=F23,"Diastolic >= systolic","OK"))))))))) -> Visit before enrollment
... A32: SUBJ-010 | B32: SITE-002 | C32: Screening | D32: 46072 | E32: 67.1 | F32: 120 | G32: 83 | H32: Complete | I32: =IF(COUNTIF(Subjects!$A$2:$A$82,A32)=0,"Subject not in register",IF(D32<INDEX(Subjects!$C$2:$C$82,MATCH(A32,Subjects!$A$2:$A$82,0)),"Visit before enrollment",IF(H32="Missed","Missed visit",IF(H32="Scheduled","OK",IF(E32="","Missing weight",IF(OR(E32<'Check Rules'!$B$5,E32>'Check Rules'!$B$6),"Weight out of range",IF(OR(F32<'Check Rules'!$B$7,F32>'Check Rules'!$B$8),"Systolic BP out of range",IF(OR(G32<'Check Rules'!$B$9,G32>'Check Rules'!$B$10),"Diastolic BP out of range",IF(G32>=F32,"Diastolic >= systolic","OK"))))))))) -> OK
A33: SUBJ-010 | B33: SITE-002 | C33: Baseline | D33: 46074 | F33: 124 | G33: 80 | H33: Complete | I33: =IF(COUNTIF(Subjects!$A$2:$A$82,A33)=0,"Subject not in register",IF(D33<INDEX(Subjects!$C$2:$C$82,MATCH(A33,Subjects!$A$2:$A$82,0)),"Visit before enrollment",IF(H33="Missed","Missed visit",IF(H33="Scheduled","OK",IF(E33="","Missing weight",IF(OR(E33<'Check Rules'!$B$5,E33>'Check Rules'!$B$6),"Weight out of range",IF(OR(F33<'Check Rules'!$B$7,F33>'Check Rules'!$B$8),"Systolic BP out of range",IF(OR(G33<'Check Rules'!$B$9,G33>'Check Rules'!$B$10),"Diastolic BP out of range",IF(G33>=F33,"Diastolic >= systolic","OK"))))))))) -> Missing weight
A34: SUBJ-010 | B34: SITE-002 | C34: Week 4 | D34: 46102 | E34: 64.7 | F34: 127 | G34: 76 | H34: Complete | I34: =IF(COUNTIF(Subjects!$A$2:$A$82,A34)=0,"Subject not in register",IF(D34<INDEX(Subjects!$C$2:$C$82,MATCH(A34,Subjects!$A$2:$A$82,0)),"Visit before enrollment",IF(H34="Missed","Missed visit",IF(H34="Scheduled","OK",IF(E34="","Missing weight",IF(OR(E34<'Check Rules'!$B$5,E34>'Check Rules'!$B$6),"Weight out of range",IF(OR(F34<'Check Rules'!$B$7,F34>'Check Rules'!$B$8),"Systolic BP out of range",IF(OR(G34<'Check Rules'!$B$9,G34>'Check Rules'!$B$10),"Diastolic BP out of range",IF(G34>=F34,"Diastolic >= systolic","OK"))))))))) -> OK
A35: SUBJ-010 | B35: SITE-002 | C35: Week 8 | D35: 46130 | E35: 66.4 | F35: 133 | G35: 77 | H35: Complete | I35: =IF(COUNTIF(Subjects!$A$2:$A$82,A35)=0,"Subject not in register",IF(D35<INDEX(Subjects!$C$2:$C$82,MATCH(A35,Subjects!$A$2:$A$82,0)),"Visit before enrollment",IF(H35="Missed","Missed visit",IF(H35="Scheduled","OK",IF(E35="","Missing weight",IF(OR(E35<'Check Rules'!$B$5,E35>'Check Rules'!$B$6),"Weight out of range",IF(OR(F35<'Check Rules'!$B$7,F35>'Check Rules'!$B$8),"Systolic BP out of range",IF(OR(G35<'Check Rules'!$B$9,G35>'Check Rules'!$B$10),"Diastolic BP out of range",IF(G35>=F35,"Diastolic >= systolic","OK"))))))))) -> OK
A36: SUBJ-011 | B36: SITE-001 | C36: Screening | D36: 46041 | E36: 54.1 | F36: 130 | G36: 74 | H36: Complete | I36: =IF(COUNTIF(Subjects!$A$2:$A$82,A36)=0,"Subject not in register",IF(D36<INDEX(Subjects!$C$2:$C$82,MATCH(A36,Subjects!$A$2:$A$82,0)),"Visit before enrollment",IF(H36="Missed","Missed visit",IF(H36="Scheduled","OK",IF(E36="","Missing weight",IF(OR(E36<'Check Rules'!$B$5,E36>'Check Rules'!$B$6),"Weight out of range",IF(OR(F36<'Check Rules'!$B$7,F36>'Check Rules'!$B$8),"Systolic BP out of range",IF(OR(G36<'Check Rules'!$B$9,G36>'Check Rules'!$B$10),"Diastolic BP out of range",IF(G36>=F36,"Diastolic >= systolic","OK"))))))))) -> OK
A37: SUBJ-011 | B37: SITE-001 | C37: Baseline | D37: 46043 | E37: 53.2 | F37: 132 | G37: 72 | H37: Complete | I37: =IF(COUNTIF(Subjects!$A$2:$A$82,A37)=0,"Subject not in register",IF(D37<INDEX(Subjects!$C$2:$C$82,MATCH(A37,Subjects!$A$2:$A$82,0)),"Visit before enrollment",IF(H37="Missed","Missed visit",IF(H37="Scheduled","OK",IF(E37="","Missing weight",IF(OR(E37<'Check Rules'!$B$5,E37>'Check Rules'!$B$6),"Weight out of range",IF(OR(F37<'Check Rules'!$B$7,F37>'Check Rules'!$B$8),"Systolic BP out of range",IF(OR(G37<'Check Rules'!$B$9,G37>'Check Rules'!$B$10),"Diastolic BP out of range",IF(G37>=F37,"Diastolic >= systolic","OK"))))))))) -> OK
A38: SUBJ-011 | B38: SITE-001 | C38: Week 4 | D38: 46071 | E38: 54.8 | F38: 113 | G38: 73 | H38: Complete | I38: =IF(COUNTIF(Subjects!$A$2:$A$82,A38)=0,"Subject not in register",IF(D38<INDEX(Subjects!$C$2:$C$82,MATCH(A38,Subjects!$A$2:$A$82,0)),"Visit before enrollment",IF(H38="Missed","Missed visit",IF(H38="Scheduled","OK",IF(E38="","Missing weight",IF(OR(E38<'Check Rules'!$B$5,E38>'Check Rules'!$B$6),"Weight out of range",IF(OR(F38<'Check Rules'!$B$7,F38>'Check Rules'!$B$8),"Systolic BP out of range",IF(OR(G38<'Check Rules'!$B$9,G38>'Check Rules'!$B$10),"Diastolic BP out of range",IF(G38>=F38,"Diastolic >= systolic","OK"))))))))) -> OK
A39: SUBJ-012 | B39: SITE-004 | C39: Screening | D39: 46067 | E39: 61.6 | F39: 143 | G39: 71 | H39: Complete | I39: =IF(COUNTIF(Subjects!$A$2:$A$82,A39)=0,"Subject not in register",IF(D39<INDEX(Subjects!$C$2:$C$82,MATCH(A39,Subjects!$A$2:$A$82,0)),"Visit before enrollment",IF(H39="Missed","Missed visit",IF(H39="Scheduled","OK",IF(E39="","Missing weight",IF(OR(E39<'Check Rules'!$B$5,E39>'Check Rules'!$B$6),"Weight out of range",IF(OR(F39<'Check Rules'!$B$7,F39>'Check Rules'!$B$8),"Systolic BP out of range",IF(OR(G39<'Check Rules'!$B$9,G39>'Check Rules'!$B$10),"Diastolic BP out of range",IF(G39>=F39,"Diastolic >= systolic","OK"))))))))) -> OK
A40: SUBJ-012 | B40: SITE-004 | C40: Baseline | D40: 46069 | E40: 62.1 | F40: 135 | G40: 76 | H40: Complete | I40: =IF(COUNTIF(Subjects!$A$2:$A$82,A40)=0,"Subject not in register",IF(D40<INDEX(Subjects!$C$2:$C$82,MATCH(A40,Subjects!$A$2:$A$82,0)),"Visit before enrollment",IF(H40="Missed","Missed visit",IF(H40="Scheduled","OK",IF(E40="","Missing weight",IF(OR(E40<'Check Rules'!$B$5,E40>'Check Rules'!$B$6),"Weight out of range",IF(OR(F40<'Check Rules'!$B$7,F40>'Check Rules'!$B$8),"Systolic BP out of range",IF(OR(G40<'Check Rules'!$B$9,G40>'Check Rules'!$B$10),"Diastolic BP out of range",IF(G40>=F40,"Diastolic >= systolic","OK"))))))))) -> OK
A41: SUBJ-012 | B41: SITE-004 | C41: Week 4 | D41: 46097 | E41: 62.1 | F41: 139 | G41: 76 | H41: Complete | I41: =IF(COUNTIF(Subjects!$A$2:$A$82,A41)=0,"Subject not in register",IF(D41<INDEX(Subjects!$C$2:$C$82,MATCH(A41,Subjects!$A$2:$A$82,0)),"Visit before enrollment",IF(H41="Missed","Missed visit",IF(H41="Scheduled","OK",IF(E41="","Missing weight",IF(OR(E41<'Check Rules'!$B$5,E41>'Check Rules'!$B$6),"Weight out of range",IF(OR(F41<'Check Rules'!$B$7,F41>'Check Rules'!$B$8),"Systolic BP out of range",IF(OR(G41<'Check Rules'!$B$9,G41>'Check Rules'!$B$10),"Diastolic BP out of range",IF(G41>=F41,"Diastolic >= systolic","OK"))))))))) -> OK
A42: SUBJ-012 | B42: SITE-004 | C42: Week 8 | D42: 46125 | E42: 62.2 | F42: 137 | G42: 75 | H42: Complete | I42: =IF(COUNTIF(Subjects!$A$2:$A$82,A42)=0,"Subject not in register",IF(D42<INDEX(Subjects!$C$2:$C$82,MATCH(A42,Subjects!$A$2:$A$82,0)),"Visit before enrollment",IF(H42="Missed","Missed visit",IF(H42="Scheduled","OK",IF(E42="","Missing weight",IF(OR(E42<'Check Rules'!$B$5,E42>'Check Rules'!$B$6),"Weight out of range",IF(OR(F42<'Check Rules'!$B$7,F42>'Check Rules'!$B$8),"Systolic BP out of range",IF(OR(G42<'Check Rules'!$B$9,G42>'Check Rules'!$B$10),"Diastolic BP out of range",IF(G42>=F42,"Diastolic >= systolic","OK"))))))))) -> OK
A43: SUBJ-013 | B43: SITE-003 | C43: Screening | D43: 46040 | E43: 72.1 | F43: 139 | G43: 83 | H43: Complete | I43: =IF(COUNTIF(Subjects!$A$2:$A$82,A43)=0,"Subject not in register",IF(D43<INDEX(Subjects!$C$2:$C$82,MATCH(A43,Subjects!$A$2:$A$82,0)),"Visit before enrollment",IF(H43="Missed","Missed visit",IF(H43="Scheduled","OK",IF(E43="","Missing weight",IF(OR(E43<'Check Rules'!$B$5,E43>'Check Rules'!$B$6),"Weight out of range",IF(OR(F43<'Check Rules'!$B$7,F43>'Check Rules'!$B$8),"Systolic BP out of range",IF(OR(G43<'Check Rules'!$B$9,G43>'Check Rules'!$B$10),"Diastolic BP out of range",IF(G43>=F43,"Diastolic >= systolic","OK"))))))))) -> OK
A44: SUBJ-013 | B44: SITE-003 | C44: Baseline | D44: 46042 | E44: 71.9 | F44: 136 | G44: 69 | H44: Complete | I44: =IF(COUNTIF(Subjects!$A$2:$A$82,A44)=0,"Subject not in register",IF(D44<INDEX(Subjects!$C$2:$C$82,MATCH(A44,Subjects!$A$2:$A$82,0)),"Visit before enrollment",IF(H44="Missed","Missed visit",IF(H44="Scheduled","OK",IF(E44="","Missing weight",IF(OR(E44<'Check Rules'!$B$5,E44>'Check Rules'!$B$6),"Weight out of range",IF(OR(F44<'Check Rules'!$B$7,F44>'Check Rules'!$B$8),"Systolic BP out of range",IF(OR(G44<'Check Rules'!$B$9,G44>'Check Rules'!$B$10),"Diastolic BP out of range",IF(G44>=F44,"Diastolic >= systolic","OK"))))))))) -> OK
A45: SUBJ-013 | B45: SITE-003 | C45: Week 4 | D45: 46070 | E45: 72.3 | F45: 124 | G45: 70 | H45: Complete | I45: =IF(COUNTIF(Subjects!$A$2:$A$82,A45)=0,"Subject not in register",IF(D45<INDEX(Subjects!$C$2:$C$82,MATCH(A45,Subjects!$A$2:$A$82,0)),"Visit before enrollment",IF(H45="Missed","Missed visit",IF(H45="Scheduled","OK",IF(E45="","Missing weight",IF(OR(E45<'Check Rules'!$B$5,E45>'Check Rules'!$B$6),"Weight out of range",IF(OR(F45<'Check Rules'!$B$7,F45>'Check Rules'!$B$8),"Systolic BP out of range",IF(OR(G45<'Check Rules'!$B$9,G45>'Check Rules'!$B$10),"Diastolic BP out of range",IF(G45>=F45,"Diastolic >= systolic","OK"))))))))) -> OK
... A105: SUBJ-031 | B105: SITE-004 | C105: Week 8 | D105: 46120 | E105: 71.8 | F105: 132 | G105: 75 | H105: Complete | I105: =IF(COUNTIF(Subjects!$A$2:$A$82,A105)=0,"Subject not in register",IF(D105<INDEX(Subjects!$C$2:$C$82,MATCH(A105,Subjects!$A$2:$A$82,0)),"Visit before enrollment",IF(H105="Missed","Missed visit",IF(H105="Scheduled","OK",IF(E105="","Missing weight",IF(OR(E105<'Check Rules'!$B$5,E105>'Check Rules'!$B$6),"Weight out of range",IF(OR(F105<'Check Rules'!$B$7,F105>'Check Rules'!$B$8),"Systolic BP out of range",IF(OR(G105<'Check Rules'!$B$9,G105>'Check Rules'!$B$10),"Diastolic BP out of range",IF(G105>=F105,"Diastolic >= systolic","OK"))))))))) -> OK
A106: SUBJ-031 | B106: SITE-004 | C106: Week 12 | D106: 46148 | H106: Scheduled | I106: =IF(COUNTIF(Subjects!$A$2:$A$82,A106)=0,"Subject not in register",IF(D106<INDEX(Subjects!$C$2:$C$82,MATCH(A106,Subjects!$A$2:$A$82,0)),"Visit before enrollment",IF(H106="Missed","Missed visit",IF(H106="Scheduled","OK",IF(E106="","Missing weight",IF(OR(E106<'Check Rules'!$B$5,E106>'Check Rules'!$B$6),"Weight out of range",IF(OR(F106<'Check Rules'!$B$7,F106>'Check Rules'!$B$8),"Systolic BP out of range",IF(OR(G106<'Check Rules'!$B$9,G106>'Check Rules'!$B$10),"Diastolic BP out of range",IF(G106>=F106,"Diastolic >= systolic","OK"))))))))) -> OK
A107: SUBJ-032 | B107: SITE-005 | C107: Screening | D107: 46075 | E107: 84.7 | F107: 119 | G107: 85 | H107: Complete | I107: =IF(COUNTIF(Subjects!$A$2:$A$82,A107)=0,"Subject not in register",IF(D107<INDEX(Subjects!$C$2:$C$82,MATCH(A107,Subjects!$A$2:$A$82,0)),"Visit before enrollment",IF(H107="Missed","Missed visit",IF(H107="Scheduled","OK",IF(E107="","Missing weight",IF(OR(E107<'Check Rules'!$B$5,E107>'Check Rules'!$B$6),"Weight out of range",IF(OR(F107<'Check Rules'!$B$7,F107>'Check Rules'!$B$8),"Systolic BP out of range",IF(OR(G107<'Check Rules'!$B$9,G107>'Check Rules'!$B$10),"Diastolic BP out of range",IF(G107>=F107,"Diastolic >= systolic","OK"))))))))) -> OK
...

Sheet Adverse Events
A1: AE_ID | B1: Subject_ID | C1: AE_Term | D1: Onset_Date | E1: Severity | F1: Seriousness | G1: Relationship | H1: Outcome | I1: Treatment_Arm | J1: Row_Check
A2: AE-001 | B2: SUBJ-034 | C2: Abdominal discomfort | D2: 46034 | E2: Mild | F2: No | G2: Possibly related | H2: Recovering | I2: =IFERROR(INDEX(Subjects!$F$2:$F$82,MATCH(B2,Subjects!$A$2:$A$82,0)),"Not in register") -> Treatment A | J2: =IF(I2="Not in register","Subject not in register",IF(D2<INDEX(Subjects!$C$2:$C$82,MATCH(B2,Subjects!$A$2:$A$82,0)),"Onset before enrollment",IF(E2="","Severity missing",IF(AND(F2<>"Yes",F2<>"No"),"Seriousness missing","OK")))) -> OK
A3: AE-002 | B3: SUBJ-064 | C3: Headache | D3: 46043 | E3: Moderate | F3: No | G3: Not related | H3: Not recovered | I3: =IFERROR(INDEX(Subjects!$F$2:$F$82,MATCH(B3,Subjects!$A$2:$A$82,0)),"Not in register") -> Treatment A | J3: =IF(I3="Not in register","Subject not in register",IF(D3<INDEX(Subjects!$C$2:$C$82,MATCH(B3,Subjects!$A$2:$A$82,0)),"Onset before enrollment",IF(E3="","Severity missing",IF(AND(F3<>"Yes",F3<>"No"),"Seriousness missing","OK")))) -> OK
A4: AE-003 | B4: SUBJ-041 | C4: Abdominal discomfort | D4: 46044 | E4: Moderate | F4: No | G4: Not related | H4: Unknown | I4: =IFERROR(INDEX(Subjects!$F$2:$F$82,MATCH(B4,Subjects!$A$2:$A$82,0)),"Not in register") -> Treatment A | J4: =IF(I4="Not in register","Subject not in register",IF(D4<INDEX(Subjects!$C$2:$C$82,MATCH(B4,Subjects!$A$2:$A$82,0)),"Onset before enrollment",IF(E4="","Severity missing",IF(AND(F4<>"Yes",F4<>"No"),"Seriousness missing","OK")))) -> OK
A5: AE-004 | B5: SUBJ-063 | C5: Dizziness | D5: 46048 | E5: Moderate | F5: No | G5: Not related | H5: Recovered | I5: =IFERROR(INDEX(Subjects!$F$2:$F$82,MATCH(B5,Subjects!$A$2:$A$82,0)),"Not in register") -> Placebo | J5: =IF(I5="Not in register","Subject not in register",IF(D5<INDEX(Subjects!$C$2:$C$82,MATCH(B5,Subjects!$A$2:$A$82,0)),"Onset before enrollment",IF(E5="","Severity missing",IF(AND(F5<>"Yes",F5<>"No"),"Seriousness missing","OK")))) -> OK
A6: AE-005 | B6: SUBJ-028 | C6: Headache | D6: 46050 | F6: No | G6: Not related | H6: Unknown | I6: =IFERROR(INDEX(Subjects!$F$2:$F$82,MATCH(B6,Subjects!$A$2:$A$82,0)),"Not in register") -> Placebo | J6: =IF(I6="Not in register","Subject not in register",IF(D6<INDEX(Subjects!$C$2:$C$82,MATCH(B6,Subjects!$A$2:$A$82,0)),"Onset before enrollment",IF(E6="","Severity missing",IF(AND(F6<>"Yes",F6<>"No"),"Seriousness missing","OK")))) -> Severity missing
A7: AE-006 | B7: SUBJ-059 | C7: Fatigue | D7: 46051 | E7: Mild | F7: No | G7: Not related | H7: Not recovered | I7: =IFERROR(INDEX(Subjects!$F$2:$F$82,MATCH(B7,Subjects!$A$2:$A$82,0)),"Not in register") -> Treatment A | J7: =IF(I7="Not in register","Subject not in register",IF(D7<INDEX(Subjects!$C$2:$C$82,MATCH(B7,Subjects!$A$2:$A$82,0)),"Onset before enrollment",IF(E7="","Severity missing",IF(AND(F7<>"Yes",F7<>"No"),"Seriousness missing","OK")))) -> OK
A8: AE-007 | B8: SUBJ-013 | C8: Rash | D8: 46054 | E8: Severe | F8: Yes | G8: Not related | H8: Recovered | I8: =IFERROR(INDEX(Subjects!$F$2:$F$82,MATCH(B8,Subjects!$A$2:$A$82,0)),"Not in register") -> Treatment A | J8: =IF(I8="Not in register","Subject not in register",IF(D8<INDEX(Subjects!$C$2:$C$82,MATCH(B8,Subjects!$A$2:$A$82,0)),"Onset before enrollment",IF(E8="","Severity missing",IF(AND(F8<>"Yes",F8<>"No"),"Seriousness missing","OK")))) -> OK
A9: AE-008 | B9: SUBJ-062 | C9: Fatigue | D9: 46055 | E9: Moderate | F9: No | G9: Possibly related | H9: Recovering | I9: =IFERROR(INDEX(Subjects!$F$2:$F$82,MATCH(B9,Subjects!$A$2:$A$82,0)),"Not in register") -> Placebo | J9: =IF(I9="Not in register","Subject not in register",IF(D9<INDEX(Subjects!$C$2:$C$82,MATCH(B9,Subjects!$A$2:$A$82,0)),"Onset before enrollment",IF(E9="","Severity missing",IF(AND(F9<>"Yes",F9<>"No"),"Seriousness missing","OK")))) -> OK
A10: AE-009 | B10: SUBJ-007 | C10: Fatigue | D10: 46059 | E10: Mild | F10: No | G10: Not related | H10: Unknown | I10: =IFERROR(INDEX(Subjects!$F$2:$F$82,MATCH(B10,Subjects!$A$2:$A$82,0)),"Not in register") -> Placebo | J10: =IF(I10="Not in register","Subject not in register",IF(D10<INDEX(Subjects!$C$2:$C$82,MATCH(B10,Subjects!$A$2:$A$82,0)),"Onset before enrollment",IF(E10="","Severity missing",IF(AND(F10<>"Yes",F10<>"No"),"Seriousness missing","OK")))) -> OK
A11: AE-010 | B11: SUBJ-064 | C11: Nausea | D11: 46059 | E11: Mild | F11: No | G11: Possibly related | H11: Recovered | I11: =IFERROR(INDEX(Subjects!$F$2:$F$82,MATCH(B11,Subjects!$A$2:$A$82,0)),"Not in register") -> Treatment A | J11: =IF(I11="Not in register","Subject not in register",IF(D11<INDEX(Subjects!$C$2:$C$82,MATCH(B11,Subjects!$A$2:$A$82,0)),"Onset before enrollment",IF(E11="","Severity missing",IF(AND(F11<>"Yes",F11<>"No"),"Seriousness missing","OK")))) -> OK
A12: AE-011 | B12: SUBJ-041 | C12: Abdominal discomfort | D12: 46064 | E12: Mild | G12: Possibly related | H12: Unknown | I12: =IFERROR(INDEX(Subjects!$F$2:$F$82,MATCH(B12,Subjects!$A$2:$A$82,0)),"Not in register") -> Treatment A | J12: =IF(I12="Not in register","Subject not in register",IF(D12<INDEX(Subjects!$C$2:$C$82,MATCH(B12,Subjects!$A$2:$A$82,0)),"Onset before enrollment",IF(E12="","Severity missing",IF(AND(F12<>"Yes",F12<>"No"),"Seriousness missing","OK")))) -> Seriousness missing
A13: AE-012 | B13: SUBJ-033 | C13: Dizziness | D13: 46068 | E13: Mild | F13: No | G13: Possibly related | H13: Recovering | I13: =IFERROR(INDEX(Subjects!$F$2:$F$82,MATCH(B13,Subjects!$A$2:$A$82,0)),"Not in register") -> Treatment A | J13: =IF(I13="Not in register","Subject not in register",IF(D13<INDEX(Subjects!$C$2:$C$82,MATCH(B13,Subjects!$A$2:$A$82,0)),"Onset before enrollment",IF(E13="","Severity missing",IF(AND(F13<>"Yes",F13<>"No"),"Seriousness missing","OK")))) -> OK
A14: AE-013 | B14: SUBJ-061 | C14: Fatigue | D14: 46068 | E14: Mild | F14: No | G14: Not related | H14: Recovered | I14: =IFERROR(INDEX(Subjects!$F$2:$F$82,MATCH(B14,Subjects!$A$2:$A$82,0)),"Not in register") -> Treatment A | J14: =IF(I14="Not in register","Subject not in register",IF(D14<INDEX(Subjects!$C$2:$C$82,MATCH(B14,Subjects!$A$2:$A$82,0)),"Onset before enrollment",IF(E14="","Severity missing",IF(AND(F14<>"Yes",F14<>"No"),"Seriousness missing","OK")))) -> OK
A15: AE-014 | B15: SUBJ-064 | C15: Nausea | D15: 46070 | E15: Mild | F15: No | G15: Related | H15: Unknown | I15: =IFERROR(INDEX(Subjects!$F$2:$F$82,MATCH(B15,Subjects!$A$2:$A$82,0)),"Not in register") -> Treatment A | J15: =IF(I15="Not in register","Subject not in register",IF(D15<INDEX(Subjects!$C$2:$C$82,MATCH(B15,Subjects!$A$2:$A$82,0)),"Onset before enrollment",IF(E15="","Severity missing",IF(AND(F15<>"Yes",F15<>"No"),"Seriousness missing","OK")))) -> OK
A16: AE-015 | B16: SUBJ-026 | C16: Rash | D16: 46071 | E16: Mild | F16: No | G16: Possibly related | H16: Recovered | I16: =IFERROR(INDEX(Subjects!$F$2:$F$82,MATCH(B16,Subjects!$A$2:$A$82,0)),"Not in register") -> Treatment A | J16: =IF(I16="Not in register","Subject not in register",IF(D16<INDEX(Subjects!$C$2:$C$82,MATCH(B16,Subjects!$A$2:$A$82,0)),"Onset before enrollment",IF(E16="","Severity missing",IF(AND(F16<>"Yes",F16<>"No"),"Seriousness missing","OK")))) -> OK
A17: AE-016 | B17: SUBJ-038 | C17: Headache | D17: 46078 | E17: Mild | F17: No | G17: Possibly related | H17: Recovered | I17: =IFERROR(INDEX(Subjects!$F$2:$F$82,MATCH(B17,Subjects!$A$2:$A$82,0)),"Not in register") -> Treatment A | J17: =IF(I17="Not in register","Subject not in register",IF(D17<INDEX(Subjects!$C$2:$C$82,MATCH(B17,Subjects!$A$2:$A$82,0)),"Onset before enrollment",IF(E17="","Severity missing",IF(AND(F17<>"Yes",F17<>"No"),"Seriousness missing","OK")))) -> OK
A18: AE-017 | B18: SUBJ-036 | C18: Abdominal discomfort | D18: 46078 | E18: Severe | F18: Yes | G18: Related | H18: Recovering | I18: =IFERROR(INDEX(Subjects!$F$2:$F$82,MATCH(B18,Subjects!$A$2:$A$82,0)),"Not in register") -> Placebo | J18: =IF(I18="Not in register","Subject not in register",IF(D18<INDEX(Subjects!$C$2:$C$82,MATCH(B18,Subjects!$A$2:$A$82,0)),"Onset before enrollment",IF(E18="","Severity missing",IF(AND(F18<>"Yes",F18<>"No"),"Seriousness missing","OK")))) -> OK
A19: AE-018 | B19: SUBJ-054 | C19: Fatigue | D19: 46079 | E19: Mild | F19: No | G19: Related | H19: Recovering | I19: =IFERROR(INDEX(Subjects!$F$2:$F$82,MATCH(B19,Subjects!$A$2:$A$82,0)),"Not in register") -> Treatment A | J19: =IF(I19="Not in register","Subject not in register",IF(D19<INDEX(Subjects!$C$2:$C$82,MATCH(B19,Subjects!$A$2:$A$82,0)),"Onset before enrollment",IF(E19="","Severity missing",IF(AND(F19<>"Yes",F19<>"No"),"Seriousness missing","OK")))) -> OK
A20: AE-019 | B20: SUBJ-032 | C20: Nausea | D20: 46080 | E20: Mild | F20: No | G20: Possibly related | H20: Not recovered | I20: =IFERROR(INDEX(Subjects!$F$2:$F$82,MATCH(B20,Subjects!$A$2:$A$82,0)),"Not in register") -> Placebo | J20: =IF(I20="Not in register","Subject not in register",IF(D20<INDEX(Subjects!$C$2:$C$82,MATCH(B20,Subjects!$A$2:$A$82,0)),"Onset before enrollment",IF(E20="","Severity missing",IF(AND(F20<>"Yes",F20<>"No"),"Seriousness missing","OK")))) -> OK
A21: AE-020 | B21: SUBJ-074 | C21: Fatigue | D21: 46083 | E21: Mild | F21: Yes | G21: Possibly related | H21: Recovered | I21: =IFERROR(INDEX(Subjects!$F$2:$F$82,MATCH(B21,Subjects!$A$2:$A$82,0)),"Not in register") -> Treatment A | J21: =IF(I21="Not in register","Subject not in register",IF(D21<INDEX(Subjects!$C$2:$C$82,MATCH(B21,Subjects!$A$2:$A$82,0)),"Onset before enrollment",IF(E21="","Severity missing",IF(AND(F21<>"Yes",F21<>"No"),"Seriousness missing","OK")))) -> OK
A22: AE-021 | B22: SUBJ-056 | C22: Dizziness | D22: 46085 | E22: Moderate | F22: No | G22: Related | H22: Recovered | I22: =IFERROR(INDEX(Subjects!$F$2:$F$82,MATCH(B22,Subjects!$A$2:$A$82,0)),"Not in register") -> Treatment A | J22: =IF(I22="Not in register","Subject not in register",IF(D22<INDEX(Subjects!$C$2:$C$82,MATCH(B22,Subjects!$A$2:$A$82,0)),"Onset before enrollment",IF(E22="","Severity missing",IF(AND(F22<>"Yes",F22<>"No"),"Seriousness missing","OK")))) -> OK
A23: AE-022 | B23: SUBJ-031 | C23: Fatigue | D23: 46085 | E23: Mild | F23: No | G23: Possibly related | H23: Recovering | I23: =IFERROR(INDEX(Subjects!$F$2:$F$82,MATCH(B23,Subjects!$A$2:$A$82,0)),"Not in register") -> Placebo | J23: =IF(I23="Not in register","Subject not in register",IF(D23<INDEX(Subjects!$C$2:$C$82,MATCH(B23,Subjects!$A$2:$A$82,0)),"Onset before enrollment",IF(E23="","Severity missing",IF(AND(F23<>"Yes",F23<>"No"),"Seriousness missing","OK")))) -> OK
A24: AE-023 | B24: SUBJ-044 | C24: Fatigue | D24: 46085 | E24: Severe | F24: No | G24: Not related | H24: Unknown | I24: =IFERROR(INDEX(Subjects!$F$2:$F$82,MATCH(B24,Subjects!$A$2:$A$82,0)),"Not in register") -> Treatment A | J24: =IF(I24="Not in register","Subject not in register",IF(D24<INDEX(Subjects!$C$2:$C$82,MATCH(B24,Subjects!$A$2:$A$82,0)),"Onset before enrollment",IF(E24="","Severity missing",IF(AND(F24<>"Yes",F24<>"No"),"Seriousness missing","OK")))) -> OK
... A61: AE-060 | B61: SUBJ-067 | C61: Nausea | D61: 46142 | E61: Mild | F61: No | G61: Not related | H61: Recovered | I61: =IFERROR(INDEX(Subjects!$F$2:$F$82,MATCH(B61,Subjects!$A$2:$A$82,0)),"Not in register") -> Placebo | J61: =IF(I61="Not in register","Subject not in register",IF(D61<INDEX(Subjects!$C$2:$C$82,MATCH(B61,Subjects!$A$2:$A$82,0)),"Onset before enrollment",IF(E61="","Severity missing",IF(AND(F61<>"Yes",F61<>"No"),"Seriousness missing","OK")))) -> OK

Sheet Data Checks
A1: Check_ID | B1: Data_Domain | C1: Record_Key | D1: Check_Type | E1: Flag_Description | F1: Review_Priority | G1: Review_Status | H1: Source_Row | I1: Live_Check_Result | J1: Query_ID
A2: SUB-001 | B2: Subjects | C2: SUBJ-011 | D2: Duplicate subject ID | E2: Subject ID appears twice in the register | F2: High | G2: Open | H2: 12 | I2: =INDEX(Subjects!$H:$H,H2) -> Duplicate subject ID | J2: QRY-001
A3: SUB-002 | B3: Subjects | C3: SUBJ-011 | D3: Duplicate subject ID | E3: Subject ID appears twice in the register | F3: High | G3: Open | H3: 82 | I3: =INDEX(Subjects!$H:$H,H3) -> Duplicate subject ID | J3: QRY-001
A4: SUB-003 | B4: Subjects | C4: SUBJ-036 | D4: Age out of range | E4: Age recorded as 17 (limit 18-85) | F4: High | G4: Resolved | H4: 37 | I4: =INDEX(Subjects!$H:$H,H4) -> OK | J4: QRY-002
A5: SUB-004 | B5: Subjects | C5: SUBJ-073 | D5: Age out of range | E5: Age recorded as 91 (limit 18-85) | F5: High | G5: Open | H5: 74 | I5: =INDEX(Subjects!$H:$H,H5) -> Age out of range | J5: QRY-003
A6: SUB-005 | B6: Subjects | C6: SUBJ-052 | D6: Missing field | E6: Sex not recorded | F6: Medium | G6: Query sent | H6: 53 | I6: =INDEX(Subjects!$H:$H,H6) -> Missing field | J6: QRY-004
A7: SUB-006 | B7: Subjects | C7: SUBJ-066 | D7: Missing field | E7: Treatment arm not recorded | F7: High | G7: Open | H7: 67 | I7: =INDEX(Subjects!$H:$H,H7) -> Missing field | J7: QRY-005
A8: VIS-001 | B8: Visits | C8: SUBJ-005|Week 4 | D8: Weight out of range | E8: Weight recorded as 718.0 kg (limit 35-200) | F8: High | G8: Resolved | H8: 19 | I8: =INDEX(Visits!$I:$I,H8) -> OK | J8: QRY-006
A9: VIS-002 | B9: Visits | C9: SUBJ-010|Baseline | D9: Missing weight | E9: Weight missing at a completed visit | F9: Medium | G9: Answered - pending update | H9: 33 | I9: =INDEX(Visits!$I:$I,H9) -> Missing weight | J9: QRY-007
A10: VIS-003 | B10: Visits | C10: SUBJ-015|Screening | D10: Systolic BP out of range | E10: Systolic BP recorded as 300 mmHg (limit 70-220) | F10: High | G10: Open | H10: 48 | I10: =INDEX(Visits!$I:$I,H10) -> Systolic BP out of range | J10: QRY-008
A11: VIS-004 | B11: Visits | C11: SUBJ-027|Week 4 | D11: Diastolic >= systolic | E11: Diastolic BP is not lower than systolic BP | F11: Medium | G11: Query sent | H11: 90 | I11: =INDEX(Visits!$I:$I,H11) -> Diastolic BP out of range | J11: QRY-009
A12: VIS-005 | B12: Visits | C12: SUBJ-031|Baseline | D12: Visit before enrollment | E12: Visit date is before the enrollment date | F12: High | G12: Open | H12: 103 | I12: =INDEX(Visits!$I:$I,H12) -> Visit before enrollment | J12: QRY-010
A13: VIS-006 | B13: Visits | C13: SUBJ-099|Screening | D13: Subject not in register | E13: Visit recorded for a subject not in the register | F13: High | G13: Open | H13: 293 | I13: =INDEX(Visits!$I:$I,H13) -> Subject not in register | J13: QRY-011
A14: VIS-007 | B14: Visits | C14: SUBJ-051|Week 4 | D14: Missed visit | E14: Visit marked as missed | F14: Low | G14: Open | H14: 180 | I14: =INDEX(Visits!$I:$I,H14) -> Missed visit | J14: QRY-012
